<?xml version='1.0'?>
<sdf version='1.4'>
  <model name="door_simple">
    <self_collide>true</self_collide>
    <static>false</static>
    <pose>0 0 0 0 0 0</pose>

    <link name="frame">

      <inertial>
        <mass>100.0</mass>
        <inertia>
          <ixx>0.013102127690</ixx>   <ixy>-0.000000514790</ixy>    <ixz>0.000000965200</ixz>
                                      <iyy>0.017339000240</iyy>     <iyz>-0.000017996010</iyz>
                                                                    <izz>0.004334337460</izz>
        </inertia>
      </inertial>

      <collision name="frame_collision">
        <geometry>
          <mesh>
            <uri>model://door_simple/meshes/frame.stl</uri>
          </mesh>
        </geometry>
      </collision>

      <visual name="frame_visual">
        <geometry>
          <mesh>
            <uri>model://door_simple/meshes/frame.stl</uri>
          </mesh>
        </geometry>
        <material>
          <script>
            <uri>file://media/materials/scripts/gazebo.material</uri>
            <name>Gazebo/WoodPallet</name>
          </script>
        </material>
      </visual>

    </link>

    <link name="door">

      <inertial>
        <mass>10.0</mass>
        <inertia>
          <ixx>0.030386862790</ixx>   <ixy>-0.000000000330</ixy>    <ixz>0.000000216760</ixz>
                                      <iyy>0.035534743650</iyy>     <iyz>-0.000000000060</iyz>
                                                                    <izz>0.005184277950</izz>
        </inertia>
      </inertial>

      <collision name="door_collision">
        <geometry>
          <mesh>
            <uri>model://door_simple/meshes/door.stl</uri>
          </mesh>
        </geometry>
      </collision>

      <visual name="door_visual">
        <geometry>
          <mesh>
            <uri>model://door_simple/meshes/door.stl</uri>
          </mesh>
        </geometry>
        <material>
          <script>
            <uri>file://media/materials/scripts/gazebo.material</uri>
            <name>Gazebo/Wood</name>
          </script>
        </material>
      </visual>

    </link>


    <link name="lever">
      <pose> 0 0.84 0.9552 0 -1.5708 0</pose>
      <inertial>
        <mass>1.0</mass>
        <inertia>
          <ixx>0.001</ixx>   <ixy>0.00</ixy>      <ixz>0.00</ixz>
                             <iyy>0.001</iyy>     <iyz>0.00</iyz>
                                                  <izz>0.001</izz>
        </inertia>
      </inertial>

      <collision name="lever_collision">
        <geometry>
          <mesh>
            <uri>model://door_simple/meshes/lever.stl</uri>
          </mesh>
        </geometry>
      </collision>

      <visual name="lever_visual">
        <geometry>
          <mesh>
            <uri>model://door_simple/meshes/lever.stl</uri>
          </mesh>
        </geometry>
        <material>
          <script>
            <uri>file://media/materials/scripts/gazebo.material</uri>
            <name>Gazebo/Gold</name>
          </script>
        </material>
      </visual>

    </link>

    <joint type="fixed" name="joint_world_frame">
      <pose>0 0 0 0 0 0</pose>
      <parent>world</parent>
      <child>frame</child>
      <physics>
        <ode>
          <implicit_spring_damper>1</implicit_spring_damper>
        </ode>
      </physics>
    </joint>

    <joint type="revolute" name="joint_frame_door">
      <pose>0 0 0 0 0 0</pose>
      <parent>frame</parent>
      <child>door</child>
      <axis>
        <xyz>0 0 1</xyz>
        <!--  self-closing hinge -->
        <!--dynamics>
          <damping>0.5</damping>
          <friction>0.01</friction>
          <spring_reference>0.0</spring_reference>
          <spring_stiffness>1</spring_stiffness>
        </dynamics-->
        <limit>
          <lower>-0.03</lower>
          <upper>1.57</upper>
        </limit>
      </axis>
      <physics>
        <ode>
          <implicit_spring_damper>1</implicit_spring_damper>
        </ode>
      </physics>
    </joint>

    <joint type="revolute" name="joint_door_lever">
      <pose>0 0 0 0 0 0</pose>
      <parent>door</parent>
      <child>lever</child>
      <axis>
        <xyz>1 0 0</xyz>
        <dynamics>
          <damping>0.5</damping>
          <friction>0.01</friction>
          <spring_reference>0.0</spring_reference>
          <spring_stiffness>3</spring_stiffness>
        </dynamics>
        <limit>
          <lower>0.0</lower>
          <upper>0.6</upper>
        </limit>
      </axis>
      <physics>
        <ode>
          <implicit_spring_damper>1</implicit_spring_damper>
        </ode>
      </physics>
    </joint>
  <plugin name="simple_door_config" filename="libsimple_door_config.so"/>
  <!-- HOKUYO -->
  
  <visual name="visual_box">
          <pose>0.25 0.2 2.0 0.0 0.0 0.0</pose>
          <geometry>
            <box>
              <size>0.05 0.05 0.05</size>
            </box>
          </geometry>
          <cast_shadows>true</cast_shadows>
          <laser_retro>100.0</laser_retro>
        </visual>
        <collision name="collision_box">
          <pose>0.0 0.0 0.0 0.0 0.0 0.0</pose>
          <max_contacts>250</max_contacts>
          <geometry>
            <box>
              <size>0.05 0.05 0.05</size>
            </box>
          </geometry>
          <surface>
            <friction>
              <ode>
                <mu>0.5</mu>
                <mu2>0.2</mu2>
                <fdir1>1.0 0 0</fdir1>
                <slip1>0</slip1>
                <slip2>0</slip2>
              </ode>
            </friction>
            <bounce>
              <restitution_coefficient>0</restitution_coefficient>
              <threshold>1000000.0</threshold>
            </bounce>
            <contact>
              <ode>
                <soft_cfm>0</soft_cfm>
                <soft_erp>0.2</soft_erp>
                <kp>1e15</kp>
                <kd>1e13</kd>
                <max_vel>100.0</max_vel>
                <min_depth>0.0001</min_depth>
              </ode>
            </contact>
          </surface>
          <laser_retro>100.0</laser_retro>
        </collision>
  
  
    <sensor type="ray" name="sonar">
          <pose>0.25 0.2 2 0 0 0</pose>
          <update_rate>5</update_rate>
          <ray>
            <scan>
              <horizontal>
                <samples>5</samples>
                <resolution>1.0</resolution>
                <min_angle>-0.25</min_angle>
                <max_angle>0.25</max_angle>
              </horizontal>
              <vertical>
                <samples>5</samples>
                <resolution>1</resolution>
                <min_angle>-0.25</min_angle>
                <max_angle>0.25</max_angle>
              </vertical>
            </scan>
            <range>
              <min>0.01</min>
              <max>0.75</max>
              <resolution>0.01</resolution>
            </range>
          </ray>
          <plugin filename="libgazebo_ros_range.so" name="gazebo_ros_range">
            <gaussianNoise>0.005</gaussianNoise>
            <alwaysOn>true</alwaysOn>
            <updateRate>5</updateRate>
            <topicName>sonar</topicName>
            <frameName>sonar_link</frameName>
            <fov>0.5</fov>
            <radiation>ultrasound</radiation>
          </plugin>
        </sensor>
  <!-- HOKUYO -->
  </model>
</sdf>
